Workbook

Sheet WBS
A1: Phase | B1: ID | C1: Task | D1: Priority | E1: Status | F1: Est. Hours | G1: Depends On | H1: Notes
A2: Phase 0 - Discovery & Requirements | B2: P0-1 | C2: Analyse company website & current digital process | D2: Must | E2: Done | F2: 3 | H2: Found: manual triage, no case tracking, no document management, no system of record
A3: Phase 0 - Discovery & Requirements | B3: P0-2 | C3: Review existing SMSSA-fe CRM repository | D3: Must | E3: Done | F3: 4 | H3: Mapped real pages/components (ClientPortal, CorporateDashboard, DocumentChecklistView, etc.)
A4: Phase 0 - Discovery & Requirements | B4: P0-3 | C4: Confirm local dev environment runs | D4: Must | E4: Done | F4: 1 | G4: P0-2 | H4: npm install / npm run dev / npm run build all verified
A5: Phase 0 - Discovery & Requirements | B5: P0-4 | C5: Interview IT manager on CRM integration approach | D5: Must | E5: Done | F5: 2 | H5: Confirmed: build AI layer around existing CRM, not a replacement
A6: Phase 0 - Discovery & Requirements | B6: P0-5 | C6: Confirm CRM API/webhook availability with IT manager | D6: Must | E6: To Do | F6: 2 | G6: P0-4 | H6: Determines integration Path A vs Path B
A7: Phase 0 - Discovery & Requirements | B7: P0-6 | C7: Draft functional & non-functional requirements document | D7: Must | E7: To Do | F7: 6 | G7: P0-1,P0-2
A8: Phase 0 - Discovery & Requirements | B8: P0-7 | C8: Get client sign-off on requirements | D8: Must | E8: To Do | F8: 2 | G8: P0-6 | H8: Needs a real email/meeting + written confirmation
A9: Phase 1 - Architecture & Design | B9: P1-1 | C9: System architecture diagram | D9: Must | E9: To Do | F9: 4 | G9: P0-5 | H9: FE, REST API, AI layer, CRM connector, mobile
A10: Phase 1 - Architecture & Design | B10: P1-2 | C10: Entity-Relationship (ER) diagram | D10: Must | E10: To Do | F10: 5 | G10: P0-5 | H10: Full database schema, dbdiagram.io/Lucidchart
A11: Phase 1 - Architecture & Design | B11: P1-3 | C11: UML Class diagram | D11: Must | E11: To Do | F11: 4 | G11: P1-2
A12: Phase 1 - Architecture & Design | B12: P1-4 | C12: UML Sequence diagram - Login/Registration flow | D12: Must | E12: To Do | F12: 3 | G12: P1-3
A13: Phase 1 - Architecture & Design | B13: P1-5 | C13: UML Sequence diagram - AI Intake Triage flow | D13: Must | E13: To Do | F13: 3 | G13: P1-3
A14: Phase 1 - Architecture & Design | B14: P1-6 | C14: Draft OpenAPI/Swagger contract | D14: Should | E14: To Do | F14: 5 | G14: P1-1 | H14: Spec for new AI-layer endpoints
A15: Phase 2 - Backend & AI Agent Layer | B15: P2-1 | C15: Scaffold backend REST API project | D15: Must | E15: To Do | F15: 4 | G15: P1-1
A16: Phase 2 - Backend & AI Agent Layer | B16: P2-2 | C16: Build CRM Integration Connector | D16: Must | E16: To Do | F16: 10 | G16: P0-5,P2-1 | H16: Path A (direct API) or Path B (companion DB)
A17: Phase 2 - Backend & AI Agent Layer | B17: P2-3 | C17: Implement Intake Triage Agent | D17: Must | E17: To Do | F17: 8 | G17: P2-2
A18: Phase 2 - Backend & AI Agent Layer | B18: P2-4 | C18: Implement Document Checklist Agent | D18: Must | E18: To Do | F18: 8 | G18: P2-2
A19: Phase 2 - Backend & AI Agent Layer | B19: P2-5 | C19: Implement Eligibility Pre-Screening Agent | D19: Should | E19: To Do | F19: 8 | G19: P2-2 | H19: Non-binding output only
A20: Phase 2 - Backend & AI Agent Layer | B20: P2-6 | C20: Implement Case Status / Client Chatbot Agent | D20: Must | E20: To Do | F20: 8 | G20: P2-2
A21: Phase 2 - Backend & AI Agent Layer | B21: P2-7 | C21: Implement Consultant Summarisation Agent | D21: Should | E21: To Do | F21: 6 | G21: P2-2
A22: Phase 2 - Backend & AI Agent Layer | B22: P2-8 | C22: Implement Visa/Permit Expiry & Renewal Agent | D22: Should | E22: To Do | F22: 6 | G22: P2-2
A23: Phase 2 - Backend & AI Agent Layer | B23: P2-9 | C23: Implement Interview/Consulate Prep Chatbot | D23: Could | E23: To Do | F23: 6 | G23: P2-2
A24: Phase 2 - Backend & AI Agent Layer | B24: P2-10 | C24: Implement AI fallback logic | D24: Must | E24: To Do | F24: 5 | G24: P2-3,P2-4 | H24: Reverts to structured form fields if AI unavailable
A25: Phase 2 - Backend & AI Agent Layer | B25: P2-11 | C25: Publish API documentation | D25: Must | E25: To Do | F25: 4 | G25: P1-6 | H25: Swagger UI or Postman collection
A26: Phase 3 - Frontend Integration | B26: P3-1 | C26: Add AI chatbot widget to ClientPortalView | D26: Must | E26: To Do | F26: 6 | G26: P2-6
A27: Phase 3 - Frontend Integration | B27: P3-2 | C27: Wire Document Checklist Agent into DocumentChecklistView | D27: Must | E27: To Do | F27: 5 | G27: P2-4
A28: Phase 3 - Frontend Integration | B28: P3-3 | C28: Add expiry/renewal alerts to DashboardView | D28: Should | E28: To Do | F28: 4 | G28: P2-8
A29: Phase 3 - Frontend Integration | B29: P3-4 | C29: Add interview prep chatbot entry point | D29: Could | E29: To Do | F29: 4 | G29: P2-9
A30: Phase 3 - Frontend Integration | B30: P3-5 | C30: Fix mobile responsiveness | D30: Should | E30: To Do | F30: 8 | H30: Known existing gap flagged in prior commit history
A31: Phase 4 - Additional Service Modules | B31: P4-1 | C31: Tax module - document extraction agent | D31: Could | E31: To Do | F31: 6 | G31: P2-2
A32: Phase 4 - Additional Service Modules | B32: P4-2 | C32: Tax module - residency/gap agent | D32: Could | E32: To Do | F32: 6 | G32: P4-1
A33: Phase 4 - Additional Service Modules | B33: P4-3 | C33: Tax module - clearance submission agent | D33: Could | E33: To Do | F33: 6 | G33: P4-2 | H33: Requires practitioner sign-off before submission
A34: Phase 4 - Additional Service Modules | B34: P4-4 | C34: Wills module - estate intake agent | D34: Could | E34: To Do | F34: 6 | G34: P2-2
A35: Phase 4 - Additional Service Modules | B35: P4-5 | C35: Wills module - will drafting agent | D35: Could | E35: To Do | F35: 6 | G35: P4-4
A36: Phase 4 - Additional Service Modules | B36: P4-6 | C36: Wills module - execution compliance checklist agent | D36: Could | E36: To Do | F36: 5 | G36: P4-5 | H36: Requires attorney sign-off before execution
A37: Phase 5 - Mobile App | B37: P5-1 | C37: Scaffold mobile app project | D37: Should | E37: To Do | F37: 5 | G37: P2-11
A38: Phase 5 - Mobile App | B38: P5-2 | C38: Implement case status screen | D38: Should | E38: To Do | F38: 6 | G38: P5-1
A39: Phase 5 - Mobile App | B39: P5-3 | C39: Implement document upload | D39: Should | E39: To Do | F39: 6 | G39: P5-1 | H39: Camera + file upload
A40: Phase 5 - Mobile App | B40: P5-4 | C40: Implement consultant/chatbot messaging | D40: Should | E40: To Do | F40: 6 | G40: P5-1,P2-6
...

Sheet Summary
A1: Phase | B1: Total Tasks | C1: Done | D1: To Do | E1: % Complete | F1: Total Est. Hours
A2: Phase 0 - Discovery & Requirements | B2: =COUNTIF(WBS!$A$2:$A$47,A2) -> 7 | C2: =COUNTIFS(WBS!$A$2:$A$47,A2,WBS!$E$2:$E$47,"Done") -> 4 | D2: =COUNTIFS(WBS!$A$2:$A$47,A2,WBS!$E$2:$E$47,"To Do") -> 3 | E2: =IFERROR(C2/B2,0) -> 0.57142857 | F2: =SUMIF(WBS!$A$2:$A$47,A2,WBS!$F$2:$F$47) -> 20
A3: Phase 1 - Architecture & Design | B3: =COUNTIF(WBS!$A$2:$A$47,A3) -> 6 | C3: =COUNTIFS(WBS!$A$2:$A$47,A3,WBS!$E$2:$E$47,"Done") -> 0 | D3: =COUNTIFS(WBS!$A$2:$A$47,A3,WBS!$E$2:$E$47,"To Do") -> 6 | E3: =IFERROR(C3/B3,0) -> 0 | F3: =SUMIF(WBS!$A$2:$A$47,A3,WBS!$F$2:$F$47) -> 24
A4: Phase 2 - Backend & AI Agent Layer | B4: =COUNTIF(WBS!$A$2:$A$47,A4) -> 11 | C4: =COUNTIFS(WBS!$A$2:$A$47,A4,WBS!$E$2:$E$47,"Done") -> 0 | D4: =COUNTIFS(WBS!$A$2:$A$47,A4,WBS!$E$2:$E$47,"To Do") -> 11 | E4: =IFERROR(C4/B4,0) -> 0 | F4: =SUMIF(WBS!$A$2:$A$47,A4,WBS!$F$2:$F$47) -> 73
A5: Phase 3 - Frontend Integration | B5: =COUNTIF(WBS!$A$2:$A$47,A5) -> 5 | C5: =COUNTIFS(WBS!$A$2:$A$47,A5,WBS!$E$2:$E$47,"Done") -> 0 | D5: =COUNTIFS(WBS!$A$2:$A$47,A5,WBS!$E$2:$E$47,"To Do") -> 5 | E5: =IFERROR(C5/B5,0) -> 0 | F5: =SUMIF(WBS!$A$2:$A$47,A5,WBS!$F$2:$F$47) -> 27
A6: Phase 4 - Additional Service Modules | B6: =COUNTIF(WBS!$A$2:$A$47,A6) -> 6 | C6: =COUNTIFS(WBS!$A$2:$A$47,A6,WBS!$E$2:$E$47,"Done") -> 0 | D6: =COUNTIFS(WBS!$A$2:$A$47,A6,WBS!$E$2:$E$47,"To Do") -> 6 | E6: =IFERROR(C6/B6,0) -> 0 | F6: =SUMIF(WBS!$A$2:$A$47,A6,WBS!$F$2:$F$47) -> 35
A7: Phase 5 - Mobile App | B7: =COUNTIF(WBS!$A$2:$A$47,A7) -> 4 | C7: =COUNTIFS(WBS!$A$2:$A$47,A7,WBS!$E$2:$E$47,"Done") -> 0 | D7: =COUNTIFS(WBS!$A$2:$A$47,A7,WBS!$E$2:$E$47,"To Do") -> 4 | E7: =IFERROR(C7/B7,0) -> 0 | F7: =SUMIF(WBS!$A$2:$A$47,A7,WBS!$F$2:$F$47) -> 23
A8: Phase 6 - QA & Compliance | B8: =COUNTIF(WBS!$A$2:$A$47,A8) -> 4 | C8: =COUNTIFS(WBS!$A$2:$A$47,A8,WBS!$E$2:$E$47,"Done") -> 0 | D8: =COUNTIFS(WBS!$A$2:$A$47,A8,WBS!$E$2:$E$47,"To Do") -> 4 | E8: =IFERROR(C8/B8,0) -> 0 | F8: =SUMIF(WBS!$A$2:$A$47,A8,WBS!$F$2:$F$47) -> 21
A9: Phase 7 - Client Handoff | B9: =COUNTIF(WBS!$A$2:$A$47,A9) -> 3 | C9: =COUNTIFS(WBS!$A$2:$A$47,A9,WBS!$E$2:$E$47,"Done") -> 0 | D9: =COUNTIFS(WBS!$A$2:$A$47,A9,WBS!$E$2:$E$47,"To Do") -> 3 | E9: =IFERROR(C9/B9,0) -> 0 | F9: =SUMIF(WBS!$A$2:$A$47,A9,WBS!$F$2:$F$47) -> 11
A10: TOTAL | B10: =SUM(B2:B9) -> 46 | C10: =SUM(C2:C9) -> 4 | D10: =SUM(D2:D9) -> 42 | E10: =IFERROR(C10/B10,0) -> 0.086956522 | F10: =SUM(F2:F9) -> 234
